Workbook

Sheet User Guide
B2: IFRS 16 / ASC 842 LEASE CALCULATOR — USER GUIDE & MODEL DOCUMENTATION
B3: Enterprise Financial Reporting & Automated Accounting Engine | Version 2.0
B5: 1. PURPOSE & EXECUTIVE SUMMARY
B6: This model provides a fully dynamic, audit-ready framework for calculating financial statement impacts under IFRS 16 (and ASC 842) Leases. It replaces legacy off-balance-sheet operating lease accounting with a unified on-balance-sheet model. Key Capabilities: • Automatically calculates Initial Lease Liability (Present Value of future payments) and Right-of-Use (ROU) Asset. • Generates Day 1 Initial Recognition and Year 1 Subsequent Measurement Journal Entries. • Dynamically builds a 20-year Amortization Schedule separating Current vs. Non-Current liabilities. • Provides instant impact analysis across Profit & Loss, Balance Sheet, and Cash Flow Statements.
B11: 2. MODEL CONVENTIONS & COLOR-CODING LEGEND
B12: Cell Style | C12: Classification | D12: Description / User Action Required
B13: Soft Yellow Fill | C13: USER INPUT | D13: Editable parameters (e.g., Lease term, rent payments, discount rate, initial costs).
B14: Soft Green Fill | C14: KEY OUTPUT | D14: Calculated key metrics (e.g., Initial Liability, ROU Asset, Depreciation). Do not overwrite.
B15: Dark Blue Header | C15: TABLE HEADER | D15: Section dividers and table column headers.
B16: Standard White | C16: FORMULA / LINKED | D16: Calculated schedule data, journal entries, or financial statement impacts.
B18: 3. STEP-BY-STEP OPERATING INSTRUCTIONS
B19: Step | C19: Action Required | D19: Detailed Guidance
B20: Step 1 | C20: Input Contract Parameters | D20: Navigate to the 'Lease Calculator' tab. Enter lease details in the Yellow input cells (C6:C13). For a new lease, simply update these cells.
B21: Step 2 | C21: Review Day 1 Recognition | D21: Check Section 2 ('Initial Accounting Measurement Outputs') for the Initial Lease Liability and capitalized ROU Asset value.
B22: Step 3 | C22: Post Day 1 Journal Entries | D22: Extract Day 1 Initial Recognition entries from Section 3 to establish the ROU Asset and Lease Obligation in your General Ledger.
B23: Step 4 | C23: Post Periodic Accounting | D23: Use Section 4 for Year 1 periodic entries or navigate to the 'Amortization Schedule' tab for subsequent annual postings.
B24: Step 5 | C24: Analyze Statement Impacts | D24: Refer to Section 5 on the 'Lease Calculator' tab to report financial impacts to leadership and stakeholders.
B26: 4. HOW TO READ & INTERPRET CALCULATOR OUTPUTS
B27: Lease Liability (PV) | C27: Calculated as PV of remaining lease payments discounted at Incremental Borrowing Rate (IBR). Reflects total financial debt obligation.
B28: ROU Asset Value | C28: Initial Liability + Direct Costs Incurred - Incentives Received + Restoration Provision. Capitalized asset on Balance Sheet.
B29: ROU Depreciation | C29: Depreciated on a straight-line basis over the shorter of useful life or lease term, charged to P&L Operating Expenses.
B30: Interest Expense | C30: Accrued on opening Lease Liability at IBR rate. Decreases over time as liability principal is repaid (front-loaded P&L impact).
B31: Current vs. Non-Current | C31: Schedule automatically splits Lease Liability into Current (<12m principal repayment) and Non-Current (>12m remaining obligation).

Sheet Lease Calculator
B2: IFRS 16 / ASC 842 DYNAMIC LEASE CALCULATOR
B3: Interactive Financial Model & Automated Journal Entry Generator
B5: 1. CONTRACT INPUT PARAMETERS (EDIT YELLOW CELLS)
B6: Lease Contract Reference | C6: HQ Office Space - Floor 5
B7: Commencement Date | C7: 2026-01-01
B8: Lease Term (Years) | C8: 5
B9: Annual Lease Payment ($) | C9: 100000
B10: Incremental Borrowing Rate (IBR %) | C10: 0.06
B11: Initial Direct Costs Incurred ($) | C11: 5000
B12: Lease Incentives Received ($) | C12: 2000
B13: Restoration / Dismantling Provision ($) | C13: 1000
B15: 2. INITIAL ACCOUNTING MEASUREMENT OUTPUTS
B16: Initial Lease Liability ($) | C16: =PV(C10, C8, -C9, 0, 0) -> 421236.38 | D16: Present Value of Future Lease Payments
B17: Initial Right-of-Use (ROU) Asset ($) | C17: =C16+C11-C12+C13 -> 425236.38 | D17: PV of Liab + Direct Costs - Incentives + Restoration
B18: Annual Straight-Line ROU Depreciation ($) | C18: =C17/C8 -> 85047.276 | D18: ROU Asset divided by Lease Term
B19: Total Undiscounted Cash Outflows ($) | C19: =C9*C8 -> 500000 | D19: Total undiscounted rent paid over term
B20: Total Estimated Finance Expense ($) | C20: =SUM('Amortization Schedule'!E6:E25) -> 78763.621 | D20: Cumulative interest over full lease term
B22: 3. DAY 1 INITIAL RECOGNITION JOURNAL ENTRIES
B23: Account Description | C23: Financial Statement | D23: Debit ($) | E23: Credit ($)
B24: Dr. Right-of-Use (ROU) Asset | C24: Balance Sheet (Non-Current Asset) | D24: =C17 -> 425236.38 | E24: 0
B25: Dr. Cash / Bank (Lease Incentive Received) | C25: Balance Sheet (Current Asset) | D25: =C12 -> 2000 | E25: 0
B26: Cr. Lease Liability | C26: Balance Sheet (Current & Non-Current) | D26: 0 | E26: =C16 -> 421236.38
B27: Cr. Cash / Bank (Initial Direct Costs Paid) | C27: Balance Sheet (Current Asset) | D27: 0 | E27: =C11 -> 5000
B28: Cr. Provision for Restoration / Dismantling | C28: Balance Sheet (Non-Current Liability) | D28: 0 | E28: =C13 -> 1000
B29: TOTAL INITIAL RECOGNITION | D29: =SUM(D24:D28) -> 427236.38 | E29: =SUM(E24:E28) -> 427236.38
B31: 4. SUBSEQUENT MEASUREMENT JOURNAL ENTRIES (YEAR 1)
B32: Account Description | C32: Financial Statement | D32: Debit ($) | E32: Credit ($)
B33: Dr. Depreciation Expense - ROU Asset | C33: Profit & Loss (Operating Expense) | D33: ='Amortization Schedule'!I6 -> 85047.276 | E33: 0
B34: Cr. Accumulated Depreciation - ROU Asset | C34: Balance Sheet (Contra-Asset) | D34: 0 | E34: ='Amortization Schedule'!I6 -> 85047.276
B35: Dr. Finance Expense (Lease Interest) | C35: Profit & Loss (Finance Cost) | D35: ='Amortization Schedule'!E6 -> 25274.183 | E35: 0
B36: Dr. Lease Liability (Principal Repayment) | C36: Balance Sheet (Liability Reduction) | D36: ='Amortization Schedule'!F6 -> 74725.817 | E36: 0
B37: Cr. Cash / Bank (Lease Payment Paid) | C37: Balance Sheet (Cash Outflow) | D37: 0 | E37: ='Amortization Schedule'!D6 -> 100000
B39: 5. FINANCIAL STATEMENT IMPACT SUMMARY (IFRS 16 VS OLD IAS 17)
B40: Financial Statement | C40: Specific Line Item Impact | D40: IFRS 16 Accounting Treatment & Behavioral Impact
B41: Profit & Loss (P&L) | C41: Operating Expense (EBITDA) | D41: REMOVED straight-line Rent Expense. Replaced by Depreciation. Operating Profit / EBITDA IMPROVES significantly.
B42: Profit & Loss (P&L) | C42: Finance Costs (Interest Expense) | D42: NEW Interest Expense added under Finance Costs. Total P&L expense is front-loaded (higher in early years).
B43: Balance Sheet | C43: Non-Current Assets | D43: NEW Right-of-Use (ROU) Asset recognized on Day 1, depreciated straight-line over the lease term.
B44: Balance Sheet | C44: Current Liabilities | D44: Current portion of Lease Liability (principal due within 12 months) presented separately.
B45: Balance Sheet | C45: Non-Current Liabilities | D45: Non-current portion of Lease Liability presented under long-term debt.
B46: Cash Flow Statement | C46: Operating Cash Flow (CFO) | D46: IMPROVES. Only the interest portion of payment is in Operating CF; principal repayment moves to Financing CF.
...

Sheet Amortization Schedule
B2: IFRS 16 LEASE LIABILITY & ROU ASSET AMORTIZATION SCHEDULE
B3: WP Reference: L-2.0 | Dynamic Formula Engine
B5: Year | C5: Beg Lease Liab ($) | D5: Lease Payment ($) | E5: Interest Expense ($) | F5: Principal Repayment ($) | G5: End Lease Liab ($) | H5: Beg ROU Asset ($) | I5: ROU Depreciation ($) | J5: End ROU Asset ($) | K5: Current Liab ($) | L5: Non-Current Liab ($) | M5: Total P&L Charge ($)
B6: 1 | C6: ='Lease Calculator'!C16 -> 421236.38 | D6: =IF(B6<='Lease Calculator'!$C$8, 'Lease Calculator'!$C$9, 0) -> 100000 | E6: =IF(B6<='Lease Calculator'!$C$8, C6*'Lease Calculator'!$C$10, 0) -> 25274.183 | F6: =IF(B6<='Lease Calculator'!$C$8, D6-E6, 0) -> 74725.817 | G6: =IF(B6<='Lease Calculator'!$C$8, C6-F6, 0) -> 346510.56 | H6: ='Lease Calculator'!C17 -> 425236.38 | I6: =IF(B6<='Lease Calculator'!$C$8, 'Lease Calculator'!$C$18, 0) -> 85047.276 | J6: =IF(B6<='Lease Calculator'!$C$8, H6-I6, 0) -> 340189.1 | K6: =IF(B6<'Lease Calculator'!$C$8, F7, G6) -> 79209.366 | L6: =IF(B6<='Lease Calculator'!$C$8, G6-K6, 0) -> 267301.19 | M6: =IF(B6<='Lease Calculator'!$C$8, E6+I6, 0) -> 110321.46
B7: 2 | C7: =IF(B7<='Lease Calculator'!$C$8, G6, 0) -> 346510.56 | D7: =IF(B7<='Lease Calculator'!$C$8, 'Lease Calculator'!$C$9, 0) -> 100000 | E7: =IF(B7<='Lease Calculator'!$C$8, C7*'Lease Calculator'!$C$10, 0) -> 20790.634 | F7: =IF(B7<='Lease Calculator'!$C$8, D7-E7, 0) -> 79209.366 | G7: =IF(B7<='Lease Calculator'!$C$8, C7-F7, 0) -> 267301.19 | H7: =IF(B7<='Lease Calculator'!$C$8, J6, 0) -> 340189.1 | I7: =IF(B7<='Lease Calculator'!$C$8, 'Lease Calculator'!$C$18, 0) -> 85047.276 | J7: =IF(B7<='Lease Calculator'!$C$8, H7-I7, 0) -> 255141.83 | K7: =IF(B7<'Lease Calculator'!$C$8, F8, G7) -> 83961.928 | L7: =IF(B7<='Lease Calculator'!$C$8, G7-K7, 0) -> 183339.27 | M7: =IF(B7<='Lease Calculator'!$C$8, E7+I7, 0) -> 105837.91
B8: 3 | C8: =IF(B8<='Lease Calculator'!$C$8, G7, 0) -> 267301.19 | D8: =IF(B8<='Lease Calculator'!$C$8, 'Lease Calculator'!$C$9, 0) -> 100000 | E8: =IF(B8<='Lease Calculator'!$C$8, C8*'Lease Calculator'!$C$10, 0) -> 16038.072 | F8: =IF(B8<='Lease Calculator'!$C$8, D8-E8, 0) -> 83961.928 | G8: =IF(B8<='Lease Calculator'!$C$8, C8-F8, 0) -> 183339.27 | H8: =IF(B8<='Lease Calculator'!$C$8, J7, 0) -> 255141.83 | I8: =IF(B8<='Lease Calculator'!$C$8, 'Lease Calculator'!$C$18, 0) -> 85047.276 | J8: =IF(B8<='Lease Calculator'!$C$8, H8-I8, 0) -> 170094.55 | K8: =IF(B8<'Lease Calculator'!$C$8, F9, G8) -> 88999.644 | L8: =IF(B8<='Lease Calculator'!$C$8, G8-K8, 0) -> 94339.623 | M8: =IF(B8<='Lease Calculator'!$C$8, E8+I8, 0) -> 101085.35
B9: 4 | C9: =IF(B9<='Lease Calculator'!$C$8, G8, 0) -> 183339.27 | D9: =IF(B9<='Lease Calculator'!$C$8, 'Lease Calculator'!$C$9, 0) -> 100000 | E9: =IF(B9<='Lease Calculator'!$C$8, C9*'Lease Calculator'!$C$10, 0) -> 11000.356 | F9: =IF(B9<='Lease Calculator'!$C$8, D9-E9, 0) -> 88999.644 | G9: =IF(B9<='Lease Calculator'!$C$8, C9-F9, 0) -> 94339.623 | H9: =IF(B9<='Lease Calculator'!$C$8, J8, 0) -> 170094.55 | I9: =IF(B9<='Lease Calculator'!$C$8, 'Lease Calculator'!$C$18, 0) -> 85047.276 | J9: =IF(B9<='Lease Calculator'!$C$8, H9-I9, 0) -> 85047.276 | K9: =IF(B9<'Lease Calculator'!$C$8, F10, G9) -> 94339.623 | L9: =IF(B9<='Lease Calculator'!$C$8, G9-K9, 0) -> 6.4028427e-10 | M9: =IF(B9<='Lease Calculator'!$C$8, E9+I9, 0) -> 96047.632
B10: 5 | C10: =IF(B10<='Lease Calculator'!$C$8, G9, 0) -> 94339.623 | D10: =IF(B10<='Lease Calculator'!$C$8, 'Lease Calculator'!$C$9, 0) -> 100000 | E10: =IF(B10<='Lease Calculator'!$C$8, C10*'Lease Calculator'!$C$10, 0) -> 5660.3774 | F10: =IF(B10<='Lease Calculator'!$C$8, D10-E10, 0) -> 94339.623 | G10: =IF(B10<='Lease Calculator'!$C$8, C10-F10, 0) -> 6.4028427e-10 | H10: =IF(B10<='Lease Calculator'!$C$8, J9, 0) -> 85047.276 | I10: =IF(B10<='Lease Calculator'!$C$8, 'Lease Calculator'!$C$18, 0) -> 85047.276 | J10: =IF(B10<='Lease Calculator'!$C$8, H10-I10, 0) -> 0 | K10: =IF(B10<'Lease Calculator'!$C$8, F11, G10) -> 6.4028427e-10 | L10: =IF(B10<='Lease Calculator'!$C$8, G10-K10, 0) -> 0 | M10: =IF(B10<='Lease Calculator'!$C$8, E10+I10, 0) -> 90707.653
B11: 6 | C11: =IF(B11<='Lease Calculator'!$C$8, G10, 0) -> 0 | D11: =IF(B11<='Lease Calculator'!$C$8, 'Lease Calculator'!$C$9, 0) -> 0 | E11: =IF(B11<='Lease Calculator'!$C$8, C11*'Lease Calculator'!$C$10, 0) -> 0 | F11: =IF(B11<='Lease Calculator'!$C$8, D11-E11, 0) -> 0 | G11: =IF(B11<='Lease Calculator'!$C$8, C11-F11, 0) -> 0 | H11: =IF(B11<='Lease Calculator'!$C$8, J10, 0) -> 0 | I11: =IF(B11<='Lease Calculator'!$C$8, 'Lease Calculator'!$C$18, 0) -> 0 | J11: =IF(B11<='Lease Calculator'!$C$8, H11-I11, 0) -> 0 | K11: =IF(B11<'Lease Calculator'!$C$8, F12, G11) -> 0 | L11: =IF(B11<='Lease Calculator'!$C$8, G11-K11, 0) -> 0 | M11: =IF(B11<='Lease Calculator'!$C$8, E11+I11, 0) -> 0
B12: 7 | C12: =IF(B12<='Lease Calculator'!$C$8, G11, 0) -> 0 | D12: =IF(B12<='Lease Calculator'!$C$8, 'Lease Calculator'!$C$9, 0) -> 0 | E12: =IF(B12<='Lease Calculator'!$C$8, C12*'Lease Calculator'!$C$10, 0) -> 0 | F12: =IF(B12<='Lease Calculator'!$C$8, D12-E12, 0) -> 0 | G12: =IF(B12<='Lease Calculator'!$C$8, C12-F12, 0) -> 0 | H12: =IF(B12<='Lease Calculator'!$C$8, J11, 0) -> 0 | I12: =IF(B12<='Lease Calculator'!$C$8, 'Lease Calculator'!$C$18, 0) -> 0 | J12: =IF(B12<='Lease Calculator'!$C$8, H12-I12, 0) -> 0 | K12: =IF(B12<'Lease Calculator'!$C$8, F13, G12) -> 0 | L12: =IF(B12<='Lease Calculator'!$C$8, G12-K12, 0) -> 0 | M12: =IF(B12<='Lease Calculator'!$C$8, E12+I12, 0) -> 0
B13: 8 | C13: =IF(B13<='Lease Calculator'!$C$8, G12, 0) -> 0 | D13: =IF(B13<='Lease Calculator'!$C$8, 'Lease Calculator'!$C$9, 0) -> 0 | E13: =IF(B13<='Lease Calculator'!$C$8, C13*'Lease Calculator'!$C$10, 0) -> 0 | F13: =IF(B13<='Lease Calculator'!$C$8, D13-E13, 0) -> 0 | G13: =IF(B13<='Lease Calculator'!$C$8, C13-F13, 0) -> 0 | H13: =IF(B13<='Lease Calculator'!$C$8, J12, 0) -> 0 | I13: =IF(B13<='Lease Calculator'!$C$8, 'Lease Calculator'!$C$18, 0) -> 0 | J13: =IF(B13<='Lease Calculator'!$C$8, H13-I13, 0) -> 0 | K13: =IF(B13<'Lease Calculator'!$C$8, F14, G13) -> 0 | L13: =IF(B13<='Lease Calculator'!$C$8, G13-K13, 0) -> 0 | M13: =IF(B13<='Lease Calculator'!$C$8, E13+I13, 0) -> 0
B14: 9 | C14: =IF(B14<='Lease Calculator'!$C$8, G13, 0) -> 0 | D14: =IF(B14<='Lease Calculator'!$C$8, 'Lease Calculator'!$C$9, 0) -> 0 | E14: =IF(B14<='Lease Calculator'!$C$8, C14*'Lease Calculator'!$C$10, 0) -> 0 | F14: =IF(B14<='Lease Calculator'!$C$8, D14-E14, 0) -> 0 | G14: =IF(B14<='Lease Calculator'!$C$8, C14-F14, 0) -> 0 | H14: =IF(B14<='Lease Calculator'!$C$8, J13, 0) -> 0 | I14: =IF(B14<='Lease Calculator'!$C$8, 'Lease Calculator'!$C$18, 0) -> 0 | J14: =IF(B14<='Lease Calculator'!$C$8, H14-I14, 0) -> 0 | K14: =IF(B14<'Lease Calculator'!$C$8, F15, G14) -> 0 | L14: =IF(B14<='Lease Calculator'!$C$8, G14-K14, 0) -> 0 | M14: =IF(B14<='Lease Calculator'!$C$8, E14+I14, 0) -> 0
B15: 10 | C15: =IF(B15<='Lease Calculator'!$C$8, G14, 0) -> 0 | D15: =IF(B15<='Lease Calculator'!$C$8, 'Lease Calculator'!$C$9, 0) -> 0 | E15: =IF(B15<='Lease Calculator'!$C$8, C15*'Lease Calculator'!$C$10, 0) -> 0 | F15: =IF(B15<='Lease Calculator'!$C$8, D15-E15, 0) -> 0 | G15: =IF(B15<='Lease Calculator'!$C$8, C15-F15, 0) -> 0 | H15: =IF(B15<='Lease Calculator'!$C$8, J14, 0) -> 0 | I15: =IF(B15<='Lease Calculator'!$C$8, 'Lease Calculator'!$C$18, 0) -> 0 | J15: =IF(B15<='Lease Calculator'!$C$8, H15-I15, 0) -> 0 | K15: =IF(B15<'Lease Calculator'!$C$8, F16, G15) -> 0 | L15: =IF(B15<='Lease Calculator'!$C$8, G15-K15, 0) -> 0 | M15: =IF(B15<='Lease Calculator'!$C$8, E15+I15, 0) -> 0
B16: 11 | C16: =IF(B16<='Lease Calculator'!$C$8, G15, 0) -> 0 | D16: =IF(B16<='Lease Calculator'!$C$8, 'Lease Calculator'!$C$9, 0) -> 0 | E16: =IF(B16<='Lease Calculator'!$C$8, C16*'Lease Calculator'!$C$10, 0) -> 0 | F16: =IF(B16<='Lease Calculator'!$C$8, D16-E16, 0) -> 0 | G16: =IF(B16<='Lease Calculator'!$C$8, C16-F16, 0) -> 0 | H16: =IF(B16<='Lease Calculator'!$C$8, J15, 0) -> 0 | I16: =IF(B16<='Lease Calculator'!$C$8, 'Lease Calculator'!$C$18, 0) -> 0 | J16: =IF(B16<='Lease Calculator'!$C$8, H16-I16, 0) -> 0 | K16: =IF(B16<'Lease Calculator'!$C$8, F17, G16) -> 0 | L16: =IF(B16<='Lease Calculator'!$C$8, G16-K16, 0) -> 0 | M16: =IF(B16<='Lease Calculator'!$C$8, E16+I16, 0) -> 0
B17: 12 | C17: =IF(B17<='Lease Calculator'!$C$8, G16, 0) -> 0 | D17: =IF(B17<='Lease Calculator'!$C$8, 'Lease Calculator'!$C$9, 0) -> 0 | E17: =IF(B17<='Lease Calculator'!$C$8, C17*'Lease Calculator'!$C$10, 0) -> 0 | F17: =IF(B17<='Lease Calculator'!$C$8, D17-E17, 0) -> 0 | G17: =IF(B17<='Lease Calculator'!$C$8, C17-F17, 0) -> 0 | H17: =IF(B17<='Lease Calculator'!$C$8, J16, 0) -> 0 | I17: =IF(B17<='Lease Calculator'!$C$8, 'Lease Calculator'!$C$18, 0) -> 0 | J17: =IF(B17<='Lease Calculator'!$C$8, H17-I17, 0) -> 0 | K17: =IF(B17<'Lease Calculator'!$C$8, F18, G17) -> 0 | L17: =IF(B17<='Lease Calculator'!$C$8, G17-K17, 0) -> 0 | M17: =IF(B17<='Lease Calculator'!$C$8, E17+I17, 0) -> 0
B18: 13 | C18: =IF(B18<='Lease Calculator'!$C$8, G17, 0) -> 0 | D18: =IF(B18<='Lease Calculator'!$C$8, 'Lease Calculator'!$C$9, 0) -> 0 | E18: =IF(B18<='Lease Calculator'!$C$8, C18*'Lease Calculator'!$C$10, 0) -> 0 | F18: =IF(B18<='Lease Calculator'!$C$8, D18-E18, 0) -> 0 | G18: =IF(B18<='Lease Calculator'!$C$8, C18-F18, 0) -> 0 | H18: =IF(B18<='Lease Calculator'!$C$8, J17, 0) -> 0 | I18: =IF(B18<='Lease Calculator'!$C$8, 'Lease Calculator'!$C$18, 0) -> 0 | J18: =IF(B18<='Lease Calculator'!$C$8, H18-I18, 0) -> 0 | K18: =IF(B18<'Lease Calculator'!$C$8, F19, G18) -> 0 | L18: =IF(B18<='Lease Calculator'!$C$8, G18-K18, 0) -> 0 | M18: =IF(B18<='Lease Calculator'!$C$8, E18+I18, 0) -> 0
... B25: 20 | C25: =IF(B25<='Lease Calculator'!$C$8, G24, 0) -> 0 | D25: =IF(B25<='Lease Calculator'!$C$8, 'Lease Calculator'!$C$9, 0) -> 0 | E25: =IF(B25<='Lease Calculator'!$C$8, C25*'Lease Calculator'!$C$10, 0) -> 0 | F25: =IF(B25<='Lease Calculator'!$C$8, D25-E25, 0) -> 0 | G25: =IF(B25<='Lease Calculator'!$C$8, C25-F25, 0) -> 0 | H25: =IF(B25<='Lease Calculator'!$C$8, J24, 0) -> 0 | I25: =IF(B25<='Lease Calculator'!$C$8, 'Lease Calculator'!$C$18, 0) -> 0 | J25: =IF(B25<='Lease Calculator'!$C$8, H25-I25, 0) -> 0 | K25: =IF(B25<'Lease Calculator'!$C$8, F26, G25) -> 0 | L25: =IF(B25<='Lease Calculator'!$C$8, G25-K25, 0) -> 0 | M25: =IF(B25<='Lease Calculator'!$C$8, E25+I25, 0) -> 0
